Workbook

Sheet Dep Cycle Time Monitoring
A1: STD Time | B1: Speed (m/min) | C1: Software Length | D1: Deposition Time duration | E1: Workweek | F1: RUN ID | G1: Tape Number | H1: Total Length (m) | I1: Tape Prepared by: | J1: Hastelloy Manufacturer | K1: Hastelloy Thickness (um) | L1: Vacuum Start Time | N1: Tape Movement Start Time | P1: Tape Movement Stop Time | R1: Open Chamber (Time) | T1: Calculated Tape Stop | U1: ION Source OFF | V1: E-Gun 1 OFF Occurrence | W1: E-Gun 2 OFF Occurrence | X1: Grids | Y1: Comments
L2: Date | M2: Time | N2: Date | O2: Time | P2: Date | Q2: Time | R2: Date | S2: Time
A3: 60 | B3: 3 | C3: =H3+120 -> 1782 | D3: =(C3/B3)/A3 -> 9.9 | E3: WW02 | F3: 571 | G3: #2900(1662-0) | H3: 1662 | I3: Julie | J3: Ulbrich 42 | K3: 37 | L3: 46027 | M3: 0.47847222 | N3: 46027 | O3: 0.62013889 | P3: 46028 | Q3: 0.032638889 | R3: 46028 | S3: 0.069444444 | T3: =O3+(D3/24) -> 1.0326389 | U3: 0 | V3: 1 | W3: 0 | X3: KTM023 | Y3: Changed cooling plate in PM2
A4: 60 | B4: 3 | C4: =H4+120 -> 1785 | D4: =(C4/B4)/A4 -> 9.9166667 | E4: WW02 | F4: 572 | G4: #2902(1665-0) | H4: 1665 | I4: Romell | J4: Ulbrich 42 | K4: 37 | L4: 46028 | M4: 0.42708333 | N4: 46028 | O4: 0.55069444 | P4: 46028 | Q4: 0.96388889 | R4: 46029 | S4: 0.0069444444 | T4: =O4+(D4/24) -> 0.96388889 | U4: 0 | V4: 0 | W4: 0 | X4: KTM027 | Y4: Changed grids: KTM023 to KTM027
A5: 60 | B5: 3 | C5: =H5+120 -> 1782 | D5: =(C5/B5)/A5 -> 9.9 | E5: WW02 | F5: 573 | G5: #2904(1662-0) | H5: 1662 | I5: Pao/Chard | J5: Ulbrich 42 | K5: 37 | L5: 46029 | M5: 0.33472222 | N5: 46029 | O5: 0.41666667 | P5: 46029 | Q5: 0.82916667 | R5: 46029 | S5: 0.86458333 | T5: =O5+(D5/24) -> 0.82916667 | U5: 0 | V5: 0 | W5: 0 | X5: KTM027 | Y5: PM5 Bearing BL,TL and O-Spring changed; PM4 IS adjusted; PM4 emitter changed due o broken insulator
A6: 60 | B6: 3 | C6: =H6+120 -> 1813 | D6: =(C6/B6)/A6 -> 10.072222 | E6: WW02 | F6: 574 | G6: #2906(1536-0) #2880(1691-1534) | H6: =1536+157 -> 1693 | I6: PLD Boys | J6: Ulbrich 42 | K6: 37 | L6: 46029 | M6: 0.98402778 | N6: 46030 | O6: 0.13263889 | P6: 46030 | Q6: 0.55277778 | R6: 46030 | S6: 0.59583333 | T6: =O6+(D6/24) -> 0.55231481 | U6: 0 | V6: 0 | W6: 0 | X6: KTM027 | Y6: PM4 & PM5 Emmitter was replaced; PM6 Chamber base cleaned; RnD PM2 OFF
A7: 60 | B7: 3 | C7: =H7+120 -> 562 | D7: =(C7/B7)/A7 -> 3.1222222 | E7: WW02 | F7: 575 | G7: #2898(985-1427) | H7: 442 | I7: Jobel | J7: Ulbrich 42 | K7: 37 | L7: 46030 | M7: 0.81875 | N7: 46030 | O7: 0.94791667 | P7: 46031 | Q7: 0.05625 | R7: 46031 | S7: 0.075 | T7: =O7+(D7/24) -> 1.0780093 | U7: 0 | V7: 0 | W7: 0 | X7: KTM027 | Y7: PM4 Emitterinsulator was cracked; PM5 Zone 4 Thermocouples was replaced; Use of MgO Pellets (4-6mm)
A8: 60 | B8: 3 | C8: =H8+120 -> 2151 | D8: =(C8/B8)/A8 -> 11.95 | E8: WW02 | F8: 576 | G8: #2898(339-985) #2892(1385-0) | H8: =646+1385 -> 2031 | I8: NG | J8: Ulbrich 42/40 | K8: 37/33 | L8: 46031 | M8: 0.14930556 | N8: 46031 | O8: 0.26944444 | P8: 46031 | Q8: 0.76736111 | R8: 46031 | S8: 0.81597222 | T8: =O8+(D8/24) -> 0.76736111 | U8: 0 | V8: 0 | W8: 0 | X8: KTM027 | Y8: Tape stop due to tape is hitting the wall of the roller, because the tape was rewinded too far to the edge of the reel)
A9: 60 | B9: 3 | C9: =H9+120 -> 1740 | D9: =(C9/B9)/A9 -> 9.6666667 | E9: WW02 | F9: 577 | G9: #2912(1620-0) | H9: 1620 | I9: NG | J9: Ulbrich 42 | K9: 37 | L9: 46031 | M9: 0.98333333 | N9: 46032 | O9: 0.11041667 | P9: 46032 | Q9: 0.51388889 | R9: 46032 | S9: 0.5625 | T9: =O9+(D9/24) -> 0.51319444 | U9: 0 | V9: 0 | W9: 0 | X9: KTM027 | Y9: PM4 Cooling plate and depo shields was replaced; RM1 Encoder guide roller adjust3mm to door side
A10: 60 | B10: 3 | C10: =H10+120 -> 1776 | D10: =(C10/B10)/A10 -> 9.8666667 | E10: WW02 | F10: 578 | G10: #2914(1656-0) | H10: 1656 | I10: Pao | J10: Ulbrich 42 | K10: 37 | L10: 46032 | M10: 0.68888889 | N10: 46032 | O10: 0.82083333 | P10: 46033 | Q10: 0.23194444 | R10: 46033 | S10: 0.275 | T10: =O10+(D10/24) -> 1.2319444 | U10: 0 | V10: 2 | W10: 0 | X10: KTM027 | Y10: PM6 Top left 2pcs of bad Bearings changed; PM5 4 roll base plate alignment was adjusted by loosening bolt at wall side top left
A11: 60 | B11: 3 | C11: =H11+120 -> 2021 | D11: =(C11/B11)/A11 -> 11.227778 | E11: WW02 | F11: 579 | G11: #2910(570-0) #2910(1076-570) #2908(825-0) | H11: 1901 | I11: NG | J11: Ulbrich 42 | K11: 37 | L11: 46033 | M11: 0.36111111 | N11: 46033 | O11: 0.49861111 | P11: 46033 | Q11: 0.96666667 | R11: 46034 | S11: 0.0034722222 | T11: =O11+(D11/24) -> 0.96643519 | U11: 0 | V11: 0 | W11: 0 | X11: KTM027 | Y11: PM2 Chamber Base cooling line cleaned
A12: 60 | B12: 3 | C12: =H12+120 -> 2865 | D12: =(C12/B12)/A12 -> 15.916667 | E12: WW03 | F12: 580 | G12: #2918(1389-0)#2920(1356-0) | H12: 2745 | I12: Kyle | J12: Ulbrich 42/40 | K12: 37/33 | L12: 46034 | M12: 0.14861111 | N12: 46034 | O12: 0.24583333 | P12: 46034 | Q12: 0.90902778 | R12: 46034 | S12: 0.95138889 | T12: =O12+(D12/24) -> 0.90902778 | U12: 0 | V12: 1 | W12: 0 | X12: KTM027 | Y12: IBAD emitter insulator was changed to new one (re-opened chamber)
A13: 60 | B13: 3 | C13: =H13+120 -> 120 | D13: =(C13/B13)/A13 -> 0.66666667 | E13: WW03 | F13: 581 | G13: #2922(1403-0) #2916(1397-700) | I13: Kyle | J13: Ulbrich 42/40 | K13: 37/33 | L13: 46034 | M13: 0.97569444 | N13: 46035 | O13: 0.088194444 | P13: 46035 | Q13: 0.60416667 | R13: 46035 | S13: 0.64236111 | T13: =O13+(D13/24) -> 0.11597222 | U13: 0 | V13: 2 | W13: 1 | X13: KTM027
A14: 60 | B14: 3 | C14: =H15+120 -> 1620 | D14: =(C14/B14)/A14 -> 9 | E14: WW03 | F14: 582 | G14: #2898(339-0)#2926(1661-926)#2926(705-0) | H14: =735+705+339 -> 1779 | I14: Kyle | J14: Ulbrich 42 | K14: 37 | L14: 46035 | M14: 0.69791667 | N14: 46035 | O14: 0.84513889 | P14: 46036 | Q14: 0.24652778 | R14: 46036 | S14: 0.28888889 | T14: =O14+(D14/24) -> 1.2201389 | U14: 0 | V14: 0 | W14: 0 | X14: KTM027
A15: 60 | B15: 3 | C15: =H16+120 -> 1560 | D15: =(C15/B15)/A15 -> 8.6666667 | E15: WW03 | F15: 583 | G15: #2930(1500-0) | H15: 1500 | I15: ES | J15: Ulbrich 42 | K15: 37 | L15: 46036 | M15: 0.64236111 | N15: 46036 | O15: 0.87361111 | P15: 46037 | Q15: 0.25486111 | R15: 46037 | S15: 0.29791667 | T15: =O15+(D15/24) -> 1.2347222 | U15: 0 | V15: 0 | W15: 0 | X15: KTM027 | Y15: PM2 Ch-Base cooling line cleaned
A16: 60 | B16: 3 | C16: =H16+120 -> 1560 | D16: =(C16/B16)/A16 -> 8.6666667 | E16: WW03 | F16: 584 | G16: #EXP1-20 | H16: 1440 | I16: IS/NG | J16: Ulbrich 42 | K16: 37 | L16: 46037 | M16: 0.46597222 | N16: 46037 | O16: 0.59930556 | P16: 46037 | Q16: 0.93402778 | R16: 46037 | S16: 0.97083333 | T16: =O16+(D16/24) -> 0.96041667 | U16: 0 | V16: 0 | W16: 0 | X16: KTM027 | Y16: Adjust 1mm to the left, 2mm to Ion source side
A17: 60 | B17: 3 | C17: =H17+120 -> 1573 | D17: =(C17/B17)/A17 -> 8.7388889 | E17: WW03 | F17: 585 | G17: #2940(1453-0) | H17: 1453 | I17: Chard | J17: Ulbrich 42 | K17: 37 | L17: 46038 | M17: 0.53611111 | N17: 46038 | O17: 0.65347222 | P17: 46039 | Q17: 0.018055556 | R17: 46039 | S17: 0.079861111 | T17: =O17+(D17/24) -> 1.0175926 | U17: 0 | V17: 1 | W17: 0 | X17: KTM023 | Y17: Changed grids: KTM027 to KTM023; Adjust 5mm to the right, 2mm to Ion source side
A18: 60 | B18: 3 | C18: =H18+120 -> 1620 | D18: =(C18/B18)/A18 -> 9 | E18: WW03 | F18: 586 | G18: #2932(1500-0) | H18: 1500 | I18: Julie/Chard | J18: Ulbrich 42 | K18: 37 | L18: 46039 | M18: 0.13888889 | N18: 46039 | O18: 0.25694444 | P18: 46039 | Q18: 0.63263889 | R18: 46039 | S18: 0.66736111 | T18: =O18+(D18/24) -> 0.63194444 | U18: 0 | V18: 0 | W18: 0 | X18: KTM023 | Y18: Adj. 5mm to the right; 2mm to IS
A19: 60 | B19: 3 | C19: =H19+120 -> 1518 | D19: =(C19/B19)/A19 -> 8.4333333 | E19: WW03 | F19: 587 | G19: #2954(1398-0) | H19: 1398 | I19: Jobel | J19: Ulbrich 40 | K19: 33 | L19: 46039 | M19: 0.69236111 | N19: 46039 | O19: 0.80555556 | P19: 46040 | Q19: 0.15694444 | R19: 46040 | S19: 0.19166667 | T19: =O19+(D19/24) -> 1.1569444 | U19: 0 | V19: 1 | W19: 0 | X19: KTM023 | Y19: Idle Power at 200W
A20: 60 | B20: 3 | C20: =H20+120 -> 2204 | D20: =(C20/B20)/A20 -> 12.244444 | E20: WW03 | F20: 588 | G20: #2952(1394-0)#2916(690-0) | H20: 2084 | I20: Pao | J20: Ulbrich 42/40 | K20: 37/33 | L20: 46040 | M20: 0.50763889 | N20: 46040 | O20: 0.59861111 | P20: 46041 | Q20: 0.11527778 | R20: 46041 | S20: 0.14444444 | T20: =O20+(D20/24) -> 1.1087963 | U20: 0 | V20: 0 | W20: 0 | X20: KTM023 | Y20: Cryopump Auto regeneration
A21: 60 | B21: 3 | C21: =H21+120 -> 618 | D21: =(C21/B21)/A21 -> 3.4333333 | E21: WW04 | F21: 589 | G21: #2898(1662-1427) #2910(1364-1101) | H21: =235+263 -> 498 | J21: Ulbrich 42 | K21: 37 | L21: 46041 | M21: 0.20347222 | N21: 46041 | O21: 0.38472222 | P21: 46041 | Q21: 0.87986111 | R21: 46041 | S21: 0.93194444 | T21: =O21+(D21/24) -> 0.52777778 | U21: 0 | V21: 0 | W21: 0 | X21: KTM023 | Y21: RnD Ion Source Scan w/ PM3 Scan
A22: 60 | B22: 3 | C22: =H22+120 -> 1802 | D22: =(C22/B22)/A22 -> 10.011111 | E22: WW04 | F22: 590 | G22: #2950(1684-898) #2950(896-0) | H22: =786+896 -> 1682 | I22: Novruz | J22: Ulbrich 42 | K22: 37 | L22: 46041 | M22: 0.99305556 | N22: 46042 | O22: 0.13958333 | P22: 46042 | Q22: 0.55833333 | R22: 46042 | S22: 0.59027778 | T22: =O22+(D22/24) -> 0.55671296 | U22: 0 | V22: 1 | W22: 0 | X22: KTM023
A23: 60 | B23: 3 | C23: =H23+120 -> 1737 | D23: =(C23/B23)/A23 -> 9.65 | E23: WW04 | F23: 591 | G23: #2942(1633-1427) #29542(1427-16) | H23: 1617 | I23: Kyle | J23: Ulbrich 42 | K23: 37 | L23: 46042 | M23: 0.81666667 | N23: 46042 | O23: 0.94930556 | P23: 46043 | Q23: 0.35138889 | R23: 46043 | S23: 0.38402778 | T23: =O23+(D23/24) -> 1.3513889 | U23: 0 | V23: 0 | W23: 1 | X23: KTM023 | Y23: PM4Emitter Assy. Change; PM2 Ch-base cleaned; EPI Crystal #2,4&6 Inficon Gold; Process Gain 50%--> 20% at 221m
A24: 60 | B24: 3 | C24: =H24+120 -> 1833 | D24: =(C24/B24)/A24 -> 10.183333 | E24: WW04 | F24: 592 | G24: #2946(339-0) #2944(1328-4) RnD+50mDMY | H24: 1713 | I24: Kyle | J24: Ulbrich 42 | K24: 37 | L24: 46043 | M24: 0.53194444 | N24: 46043 | O24: 0.65347222 | P24: 46044 | Q24: 0.077777778 | R24: 46044 | S24: 0.13055556 | T24: =O24+(D24/24) -> 1.0777778 | U24: 0 | V24: 1 | W24: 0 | X24: KTM023 | Y24: Changed V-spring PM5; Changed depo shields & copper cooling plate in PM4
A25: 60 | B25: 3 | C25: =H25+120 -> 2248 | D25: =(C25/B25)/A25 -> 12.488889 | E25: WW04 | F25: 593 | G25: #2948(1656-906)#2956(1398-0) | H25: =1378+750 -> 2128 | I25: Ranne | J25: Ulbrich 42/40 | K25: 37/33 | L25: 46044 | M25: 0.21458333 | N25: 46044 | O25: 0.34305556 | P25: 46044 | Q25: 0.86805556 | R25: 46044 | S25: 0.94097222 | T25: =O25+(D25/24) -> 0.86342593 | U25: 0 | V25: 5 | W25: 0 | X25: KTM023 | Y25: PM5 Changed O-spring and V-spring; PM5 BL #1-5
A26: 60 | B26: 3 | C26: =H26+120 -> 120 | D26: =(C26/B26)/A26 -> 0.66666667 | E26: WW04 | F26: 594 | G26: #2868 (000-195)#2944 (1659-1328)#2946 (339-1665) RnD | I26: Pao/Jowi/Jobel | J26: Ulbrich 42 | K26: 37 | L26: 46045 | M26: 0.22222222 | N26: 46045 | O26: 0.27152778 | P26: 46046 | Q26: 0.069444444 | R26: 46046 | S26: 0.1125 | T26: =O26+(D26/24) -> 0.29930556 | U26: 0 | V26: 1 | W26: 0 | X26: KTM023 | Y26: PM5 -T.L. Added 0.95mm spacer at the back side. #0 bearing changed, All 6910CE bearings were changed to new. PM6-T.L. All 6910CE bearings were changed to new.B.L. #1,2,3,4,5 bearings changed to new.
A27: 60 | B27: 3 | C27: =H27+120 -> 2337 | D27: =(C27/B27)/A27 -> 12.983333 | E27: WW04 | F27: 595 | G27: #2928(1666-844) #2960(1395-0) | H27: 2217 | I27: John | J27: Ulbrich 42/40 | K27: 37/33 | L27: 46046 | M27: 0.20347222 | N27: 46046 | O27: 0.34375 | P27: 46046 | Q27: 0.88541667 | R27: 46046 | S27: 0.92361111 | T27: =O27+(D27/24) -> 0.88472222 | U27: 0 | V27: 1 | W27: 0 | X27: KTM023 | Y27: PM1 TL #2,3 ; BL #2,3,4,5
A28: 60 | B28: 3 | C28: =H28+120 -> 1646 | D28: =(C28/B28)/A28 -> 9.1444444 | E28: WW04 | F28: 596 | G28: #2958(1531-355) #2958(350-000) | H28: 1526 | I28: Deniz | J28: Ulbrich 42 | K28: 37 | L28: 46046 | M28: 0.97777778 | N28: 46047 | O28: 0.13333333 | P28: 46047 | Q28: 0.51458333 | R28: 46047 | S28: 0.55277778 | T28: =O28+(D28/24) -> 0.51435185 | U28: 0 | V28: 0 | W28: 0 | X28: KTM023
A29: 60 | B29: 3 | C29: =H29+120 -> 1517 | D29: =(C29/B29)/A29 -> 8.4277778 | E29: WW05 | F29: 597 | G29: #2970(962-697)#2964(1397-0) | H29: 1397 | I29: Ranne | J29: Ulbrich 42/40 | K29: 37/33 | L29: 46047 | M29: 0.59652778 | N29: 46047 | O29: 0.70833333 | P29: 46048 | Q29: 0.12777778 | R29: 46048 | S29: 0.17222222 | T29: =O29+(D29/24) -> 1.0594907 | U29: 0 | V29: 0 | W29: 0 | X29: KTM023
A30: 60 | B30: 3 | C30: =H30+120 -> 1648 | D30: =(C30/B30)/A30 -> 9.1555556 | E30: WW05 | F30: 598 | G30: #2970(680-0)#2968(848-0) | H30: =848+680 -> 1528 | I30: Deniz | J30: Ulbrich 42 | K30: 37 | L30: 46048 | M30: 0.32083333 | N30: 46048 | O30: 0.40069444 | P30: 46048 | Q30: 0.78333333 | R30: 46048 | S30: 0.84027778 | T30: =O30+(D30/24) -> 0.78217593 | U30: 0 | V30: 0 | W30: 0 | X30: KTM023
A31: 60 | B31: 3 | C31: =H31+120 -> 344 | D31: =(C31/B31)/A31 -> 1.9111111 | E31: WW05 | F31: 599 | G31: #2920(1556-1656)#2978(1100-1224) | H31: 224 | I31: Melo | J31: Ulbrich 42 | K31: 37 | L31: 46049 | M31: 0.069444444 | N31: 46049 | O31: 0.14375 | P31: 46049 | Q31: 0.34375 | R31: 46049 | S31: 0.35763889 | T31: =O31+(D31/24) -> 0.22337963 | U31: 0 | V31: 0 | W31: 0 | X31: KTM023 | Y31: YELLOW BUFFER DEPOSITION
A32: 60 | B32: 3 | C32: =H32+120 -> 2016 | D32: =(C32/B32)/A32 -> 11.2 | E32: WW05 | F32: 600 | G32: #2978(500-0)#2986(1396-0) | H32: 1896 | I32: Jobel | J32: Ulbrich 42/40 | K32: 37/33 | L32: 46050 | M32: 0.625 | N32: 46050 | T32: =O32+(D32/24) -> 0.46666667 | U32: 0 | V32: 0 | W32: 0 | X32: R009 | Y32: DEPO CANCELLED!! Grids change KTM023 --> R009; Re-installed old target due to arcing (2x); Changed top shield & target shield, HV connection polished, Tape cut @PM5 and PM6 during SP KM DMY ramp up
A33: 60 | B33: 3 | C33: =H33+120 -> 2016 | D33: =(C33/B33)/A33 -> 11.2 | E33: WW05 | F33: 601 | G33: #2986(1396-0) #2978(500-0) | H33: =1396+500 -> 1896 | L33: 46050 | M33: 0.79166667 | N33: 46050 | O33: 0.89861111 | P33: 46051 | Q33: 0.45833333 | R33: 46051 | S33: 0.50902778 | T33: =O33+(D33/24) -> 1.3652778 | U33: 0 | V33: 0 | W33: 0 | X33: R009 | Y33: New MgO Pellets(4-6mm); New PM6 Target; Change Top Shield and target shield,HV connection polish
A34: 60 | B34: 3 | C34: =H34+120 -> 2410 | D34: =(C34/B34)/A34 -> 13.388889 | E34: WW05 | F34: 602 | G34: #2976(896-0) #2966(1394-0) | H34: =896+1394 -> 2290 | L34: 46052 | M34: 0.52986111 | N34: 46052 | O34: 0.69236111 | P34: 46053 | Q34: 0.25069444 | R34: 46053 | S34: 0.29027778 | T34: =O34+(D34/24) -> 1.2502315 | U34: 0 | V34: 0 | W34: 0 | X34: KTM027 | Y34: DEPO CANCELLED!! Grids change R009 --> KTM027; Bolted Target Base PM6; PM6 Target changed; PM1 Target changed; Tape Cut @ 2471 No end etching profile
A35: 60 | B35: 3 | C35: =H35+120 -> 2116 | D35: =(C35/B35)/A35 -> 11.755556 | E35: WW05 | F35: 603 | G35: #2978(500-1100)#2988(1396-0) | H35: =1396+600 -> 1996 | I35: Pao | J35: Ulbrich 42/40 | K35: 37 | L35: 46053 | M35: 0.37986111 | N35: 46053 | O35: 0.54722222 | P35: 46054 | Q35: 0.055555556 | R35: 46054 | S35: 0.084027778 | T35: =O35+(D35/24) -> 1.037037 | U35: 0 | V35: 0 | W35: 0 | X35: KTM027
A36: 60 | B36: 3 | C36: =H36+120 -> 120 | D36: =(C36/B36)/A36 -> 0.66666667 | E36: WW05 | F36: 604 | G36: RnD | I36: Evgenii | L36: 46054 | M36: 0.13263889 | N36: 46054 | O36: 0.30555556 | P36: 46054 | Q36: 0.53680556 | R36: 46054 | S36: 0.0625 | T36: =O36+(D36/24) -> 0.33333333 | U36: 0 | V36: 0 | W36: 0 | X36: KTM027
A37: 60 | B37: 3 | C37: =H37+120 -> 2151 | D37: =(C37/B37)/A37 -> 11.95 | E37: WW06 | F37: 605 | G37: #3004(1361-000) #2962(670-000) | H37: =1361+670 -> 2031 | I37: Jobel | J37: Ulbrich 42/40 | K37: 35/37 | L37: 46054 | M37: 0.71180556 | N37: 46054 | O37: 0.84166667 | P37: 46055 | Q37: 0.33958333 | R37: 46055 | S37: 0.38333333 | T37: =O37+(D37/24) -> 1.3395833 | U37: 0 | V37: 2 | W37: 0 | X37: KTM027 | Y37: PM1 Target changed to Toshima
A38: 60 | B38: 3 | C38: =H38+120 -> 120 | D38: =(C38/B38)/A38 -> 0.66666667 | E38: WW06 | F38: 606 | G38: #3000(19-359) #3000(483-1058) #2982(1365-0) | I38: Jowi/Melo | J38: Ulbrich 40 | K38: 35 | L38: 46058 | M38: 0.65069444 | N38: 46058 | O38: 0.79097222 | P38: 46059 | Q38: 0.34652778 | R38: 46059 | S38: 0.38819444 | T38: =O38+(D38/24) -> 0.81875 | U38: 0 | V38: 0 | W38: 0 | X38: KTM027 | Y38: PM2 Ch-Base cooling line cleaned; PM5 BL#1,2,3,5,6,7 bearings changed; New Cygnus
A39: 60 | B39: 3 | C39: =H39+120 -> 120 | D39: =(C39/B39)/A39 -> 0.66666667 | E39: WW06 | F39: 607 | G39: #3010(1-336)#3010(336-631) | I39: Jobel | J39: Ulbrich/Subra B/BCA | L39: 46059 | M39: 0.48055556 | N39: 46059 | O39: 0.63055556 | P39: 46059 | Q39: 0.8625 | R39: 46059 | S39: 0.90416667 | T39: =O39+(D39/24) -> 0.65833333 | U39: 0 | V39: 0 | W39: 0 | X39: KTM027 | Y39: PM6 Allignment, cleaned o-ring
E40: WW06 | F40: 608 | G40: #3012(1098-0)#3014(1380-0) | H40: 2478 | I40: Evgenii | J40: Ulbrich 40 | K40: 35 | L40: 46060 | M40: 0.090277778 | N40: 46060 | O40: 0.21527778 | P40: 46060 | Q40: 0.81666667 | R40: 46060 | S40: 0.85763889 | T40: =O40+(D40/24) -> 0.21527778 | U40: 2 | V40: 0 | W40: 0 | X40: KTM027 | Y40: PM4: Depo Shields,Cooling Plate and Emitter Assy changed; PM2 Cooling plate changed, Ch-base cleaned
...

Sheet Effective Working Time
A1: Work Week | B1: Work Week Date | C1: Vacuum Start Time | E1: Tape Movement Start Time | G1: Tape Movement Stop Time | I1: Open Chamber (Time) | M1: Vacuum to Tape Movement Start | N1: Deposition Time | O1: Tape Movement Stop to Open Chamber | P1: Chambers Clean, Setup, and Maintenance | S1: Vacuum, aditional work | T1: Deposition time | U1: Time to stop, aditional work | V1: Cleaning, Maintenance | Y1: Total time (min) | Z1: Vacuum, aditional work (%) | AA1: Deposition time (%) | AB1: Time to stop, aditional work (%) | AC1: Cleaning, Maintenance (%)
C2: Date | D2: Time | E2: Date | F2: Time | G2: Date | H2: Time | I2: Date | J2: Time
A3: WW02 | B3: 01.05-01.11 | C3: 46027 | D3: 0.47847222 | E3: 46027 | F3: 0.62013889 | G3: 46028 | H3: 0.032638889 | I3: 46028 | J3: 0.069444444 | M3: =(E3+F3)-(C3+D3) -> 0.14166667 | N3: =(G3+H3)-(E3+F3) -> 0.4125 | O3: =(I3+J3)-(G3+H3) -> 0.036805556 | P3: =(C4+D4)-(I3+J3) -> 0.35763889 | S3: =1440*M3 -> 204 | T3: =1440*N3 -> 594 | U3: =1440*O3 -> 53 | V3: =1440*P3 -> 515 | X3: Total,min | Y3: 11000 | Z3: =SUM(S3:S11) -> 1644 | AA3: =SUM(T3:T11) -> 5108 | AB3: =SUM(U3:U11) -> 510 | AC3: =SUM(V3:V11) -> 2343
A4: WW02 | B4: 01.05-01.11 | C4: 46028 | D4: 0.42708333 | E4: 46028 | F4: 0.55069444 | G4: 46028 | H4: 0.96388889 | I4: 46029 | J4: 0.0069444444 | M4: =(E4+F4)-(C4+D4) -> 0.12361111 | N4: =(G4+H4)-(E4+F4) -> 0.41319444 | O4: =(I4+J4)-(G4+H4) -> 0.043055556 | P4: =(C5+D5)-(I4+J4) -> 0.32777778 | S4: =1440*M4 -> 178 | T4: =1440*N4 -> 595 | U4: =1440*O4 -> 62 | V4: =1440*P4 -> 472 | Z4: =(Z3/Y3)*100 -> 14.945455 | AA4: =(AA3/Y3)*100 -> 46.436364 | AB4: =(AB3/Y3)*100 -> 4.6363636 | AC4: =(AC3/Y3)*100 -> 21.3
A5: WW02 | B5: 01.05-01.11 | C5: 46029 | D5: 0.33472222 | E5: 46029 | F5: 0.41666667 | G5: 46029 | H5: 0.82916667 | I5: 46029 | J5: 0.86458333 | M5: =(E5+F5)-(C5+D5) -> 0.081944444 | N5: =(G5+H5)-(E5+F5) -> 0.4125 | O5: =(I5+J5)-(G5+H5) -> 0.035416667 | P5: =(C6+D6)-(I5+J5) -> 0.11944444 | S5: =1440*M5 -> 118 | T5: =1440*N5 -> 594 | U5: =1440*O5 -> 51 | V5: =1440*P5 -> 172
A6: WW02 | B6: 01.05-01.11 | C6: 46029 | D6: 0.98402778 | E6: 46030 | F6: 0.13263889 | G6: 46030 | H6: 0.55277778 | I6: 46030 | J6: 0.59583333 | M6: =(E6+F6)-(C6+D6) -> 0.14861111 | N6: =(G6+H6)-(E6+F6) -> 0.42013889 | O6: =(I6+J6)-(G6+H6) -> 0.043055556 | P6: =(C7+D7)-(I6+J6) -> 0.22291667 | S6: =1440*M6 -> 214 | T6: =1440*N6 -> 605 | U6: =1440*O6 -> 62 | V6: =1440*P6 -> 321
A7: WW02 | B7: 01.05-01.11 | C7: 46030 | D7: 0.81875 | E7: 46030 | F7: 0.94791667 | G7: 46031 | H7: 0.05625 | I7: 46031 | J7: 0.075 | M7: =(E7+F7)-(C7+D7) -> 0.12916667 | N7: =(G7+H7)-(E7+F7) -> 0.10833333 | O7: =(I7+J7)-(G7+H7) -> 0.01875 | P7: =(C8+D8)-(I7+J7) -> 0.074305556 | S7: =1440*M7 -> 186 | T7: =1440*N7 -> 156 | U7: =1440*O7 -> 27 | V7: =1440*P7 -> 107
A8: WW02 | B8: 01.05-01.11 | C8: 46031 | D8: 0.14930556 | E8: 46031 | F8: 0.26944444 | G8: 46031 | H8: 0.76736111 | I8: 46031 | J8: 0.81597222 | M8: =(E8+F8)-(C8+D8) -> 0.12013889 | N8: =(G8+H8)-(E8+F8) -> 0.49791667 | O8: =(I8+J8)-(G8+H8) -> 0.048611111 | P8: =(C9+D9)-(I8+J8) -> 0.16736111 | S8: =1440*M8 -> 173 | T8: =1440*N8 -> 717 | U8: =1440*O8 -> 70 | V8: =1440*P8 -> 241
A9: WW02 | B9: 01.05-01.11 | C9: 46031 | D9: 0.98333333 | E9: 46032 | F9: 0.11041667 | G9: 46032 | H9: 0.51388889 | I9: 46032 | J9: 0.5625 | M9: =(E9+F9)-(C9+D9) -> 0.12708333 | N9: =(G9+H9)-(E9+F9) -> 0.40347222 | O9: =(I9+J9)-(G9+H9) -> 0.048611111 | P9: =(C10+D10)-(I9+J9) -> 0.12638889 | S9: =1440*M9 -> 183 | T9: =1440*N9 -> 581 | U9: =1440*O9 -> 70 | V9: =1440*P9 -> 182
A10: WW02 | B10: 01.05-01.11 | C10: 46032 | D10: 0.68888889 | E10: 46032 | F10: 0.82083333 | G10: 46033 | H10: 0.23194444 | I10: 46033 | J10: 0.275 | M10: =(E10+F10)-(C10+D10) -> 0.13194444 | N10: =(G10+H10)-(E10+F10) -> 0.41111111 | O10: =(I10+J10)-(G10+H10) -> 0.043055556 | P10: =(C11+D11)-(I10+J10) -> 0.086111111 | S10: =1440*M10 -> 190 | T10: =1440*N10 -> 592 | U10: =1440*O10 -> 62 | V10: =1440*P10 -> 124
A11: WW02 | B11: 01.05-01.11 | C11: 46033 | D11: 0.36111111 | E11: 46033 | F11: 0.49861111 | G11: 46033 | H11: 0.96666667 | I11: 46034 | J11: 0.0034722222 | M11: =(E11+F11)-(C11+D11) -> 0.1375 | N11: =(G11+H11)-(E11+F11) -> 0.46805556 | O11: =(I11+J11)-(G11+H11) -> 0.036805556 | P11: =(C12+D12)-(I11+J11) -> 0.14513889 | S11: =1440*M11 -> 198 | T11: =1440*N11 -> 674 | U11: =1440*O11 -> 53 | V11: =1440*P11 -> 209
A12: WW03 | B12: 01.12-01.18 | C12: 46034 | D12: 0.14861111 | E12: 46034 | F12: 0.24583333 | G12: 46034 | H12: 0.90902778 | I12: 46034 | J12: 0.95138889 | M12: =(E12+F12)-(C12+D12) -> 0.097222222 | N12: =(G12+H12)-(E12+F12) -> 0.66319444 | O12: =(I12+J12)-(G12+H12) -> 0.042361111 | P12: =(C13+D13)-(I12+J12) -> 0.024305556 | S12: =1440*M12 -> 140 | T12: =1440*N12 -> 955 | U12: =1440*O12 -> 61 | V12: =1440*P12 -> 35 | X12: Total,min | Y12: 11000 | Z12: =SUM(S12:S20) -> 1672 | AA12: =SUM(T12:T20) -> 5623 | AB12: =SUM(U12:U20) -> 523 | AC12: =SUM(V12:V20) -> 2341
A13: WW03 | B13: 01.12-01.18 | C13: 46034 | D13: 0.97569444 | E13: 46035 | F13: 0.088194444 | G13: 46035 | H13: 0.60416667 | I13: 46035 | J13: 0.64236111 | M13: =(E13+F13)-(C13+D13) -> 0.1125 | N13: =(G13+H13)-(E13+F13) -> 0.51597222 | O13: =(I13+J13)-(G13+H13) -> 0.038194444 | P13: =(C14+D14)-(I13+J13) -> 0.055555556 | S13: =1440*M13 -> 162 | T13: =1440*N13 -> 743 | U13: =1440*O13 -> 55 | V13: =1440*P13 -> 80 | Z13: =(Z12/Y12)*100 -> 15.2 | AA13: =(AA12/Y12)*100 -> 51.118182 | AB13: =(AB12/Y12)*100 -> 4.7545455 | AC13: =(AC12/Y12)*100 -> 21.281818
A14: WW03 | B14: 01.12-01.18 | C14: 46035 | D14: 0.69791667 | E14: 46035 | F14: 0.84513889 | G14: 46036 | H14: 0.24652778 | I14: 46036 | J14: 0.28888889 | M14: =(E14+F14)-(C14+D14) -> 0.14722222 | N14: =(G14+H14)-(E14+F14) -> 0.40138889 | O14: =(I14+J14)-(G14+H14) -> 0.042361111 | P14: =(C15+D15)-(I14+J14) -> 0.35347222 | S14: =1440*M14 -> 212 | T14: =1440*N14 -> 578 | U14: =1440*O14 -> 61 | V14: =1440*P14 -> 509
A15: WW03 | B15: 01.12-01.18 | C15: 46036 | D15: 0.64236111 | E15: 46036 | F15: 0.87361111 | G15: 46037 | H15: 0.25486111 | I15: 46037 | J15: 0.29791667 | M15: =(E15+F15)-(C15+D15) -> 0.23125 | N15: =(G15+H15)-(E15+F15) -> 0.38125 | O15: =(I15+J15)-(G15+H15) -> 0.043055556 | P15: =(C16+D16)-(I15+J15) -> 0.16805556 | S15: =1440*M15 -> 333 | T15: =1440*N15 -> 549 | U15: =1440*O15 -> 62 | V15: =1440*P15 -> 242
A16: WW03 | B16: 01.12-01.18 | C16: 46037 | D16: 0.46597222 | E16: 46037 | F16: 0.59930556 | G16: 46037 | H16: 0.93402778 | I16: 46037 | J16: 0.97083333 | M16: =(E16+F16)-(C16+D16) -> 0.13333333 | N16: =(G16+H16)-(E16+F16) -> 0.33472222 | O16: =(I16+J16)-(G16+H16) -> 0.036805556 | P16: =(C17+D17)-(I16+J16) -> 0.56527778 | S16: =1440*M16 -> 192 | T16: =1440*N16 -> 482 | U16: =1440*O16 -> 53 | V16: =1440*P16 -> 814
A17: WW03 | B17: 01.12-01.18 | C17: 46038 | D17: 0.53611111 | E17: 46038 | F17: 0.65347222 | G17: 46039 | H17: 0.018055556 | I17: 46039 | J17: 0.079861111 | M17: =(E17+F17)-(C17+D17) -> 0.11736111 | N17: =(G17+H17)-(E17+F17) -> 0.36458333 | O17: =(I17+J17)-(G17+H17) -> 0.061805556 | P17: =(C18+D18)-(I17+J17) -> 0.059027778 | S17: =1440*M17 -> 169 | T17: =1440*N17 -> 525 | U17: =1440*O17 -> 89 | V17: =1440*P17 -> 85
A18: WW03 | B18: 01.12-01.18 | C18: 46039 | D18: 0.13888889 | E18: 46039 | F18: 0.25694444 | G18: 46039 | H18: 0.63263889 | I18: 46039 | J18: 0.66736111 | M18: =(E18+F18)-(C18+D18) -> 0.11805556 | N18: =(G18+H18)-(E18+F18) -> 0.37569444 | O18: =(I18+J18)-(G18+H18) -> 0.034722222 | P18: =(C19+D19)-(I18+J18) -> 0.025 | S18: =1440*M18 -> 170 | T18: =1440*N18 -> 541 | U18: =1440*O18 -> 50 | V18: =1440*P18 -> 36
A19: WW03 | B19: 01.12-01.18 | C19: 46039 | D19: 0.69236111 | E19: 46039 | F19: 0.80555556 | G19: 46040 | H19: 0.15694444 | I19: 46040 | J19: 0.19166667 | M19: =(E19+F19)-(C19+D19) -> 0.11319444 | N19: =(G19+H19)-(E19+F19) -> 0.35138889 | O19: =(I19+J19)-(G19+H19) -> 0.034722222 | P19: =(C20+D20)-(I19+J19) -> 0.31597222 | S19: =1440*M19 -> 163 | T19: =1440*N19 -> 506 | U19: =1440*O19 -> 50 | V19: =1440*P19 -> 455
A20: WW03 | B20: 01.12-01.18 | C20: 46040 | D20: 0.50763889 | E20: 46040 | F20: 0.59861111 | G20: 46041 | H20: 0.11527778 | I20: 46041 | J20: 0.14444444 | M20: =(E20+F20)-(C20+D20) -> 0.090972222 | N20: =(G20+H20)-(E20+F20) -> 0.51666667 | O20: =(I20+J20)-(G20+H20) -> 0.029166667 | P20: =(C21+D21)-(I20+J20) -> 0.059027778 | S20: =1440*M20 -> 131 | T20: =1440*N20 -> 744 | U20: =1440*O20 -> 42 | V20: =1440*P20 -> 85
A21: WW04 | B21: 01.19-01.25 | C21: 46041 | D21: 0.20347222 | E21: 46041 | F21: 0.38472222 | G21: 46041 | H21: 0.87986111 | I21: 46041 | J21: 0.93194444 | M21: =(E21+F21)-(C21+D21) -> 0.18125 | N21: =(G21+H21)-(E21+F21) -> 0.49513889 | O21: =(I21+J21)-(G21+H21) -> 0.052083333 | P21: =(C22+D22)-(I21+J21) -> 0.061111111 | S21: =1440*M21 -> 261 | T21: =1440*N21 -> 713 | U21: =1440*O21 -> 75 | V21: =1440*P21 -> 88 | X21: Total,min | Y21: 11000 | Z21: =SUM(S21:S28) -> 1520 | AA21: =SUM(T21:T28) -> 5740 | AB21: =SUM(U21:U28) -> 521 | AC21: =SUM(V21:V28) -> 1425
A22: WW04 | B22: 01.19-01.25 | C22: 46041 | D22: 0.99305556 | E22: 46042 | F22: 0.13958333 | G22: 46042 | H22: 0.55833333 | I22: 46042 | J22: 0.59027778 | M22: =(E22+F22)-(C22+D22) -> 0.14652778 | N22: =(G22+H22)-(E22+F22) -> 0.41875 | O22: =(I22+J22)-(G22+H22) -> 0.031944444 | P22: =(C23+D23)-(I22+J22) -> 0.22638889 | S22: =1440*M22 -> 211 | T22: =1440*N22 -> 603 | U22: =1440*O22 -> 46 | V22: =1440*P22 -> 326 | Z22: =(Z21/Y21)*100 -> 13.818182 | AA22: =(AA21/Y21)*100 -> 52.181818 | AB22: =(AB21/Y21)*100 -> 4.7363636 | AC22: =(AC21/Y21)*100 -> 12.954545
A23: WW04 | B23: 01.19-01.25 | C23: 46042 | D23: 0.81666667 | E23: 46042 | F23: 0.94930556 | G23: 46043 | H23: 0.35138889 | I23: 46043 | J23: 0.38402778 | M23: =(E23+F23)-(C23+D23) -> 0.13263889 | N23: =(G23+H23)-(E23+F23) -> 0.40208333 | O23: =(I23+J23)-(G23+H23) -> 0.032638889 | P23: =(C24+D24)-(I23+J23) -> 0.14791667 | S23: =1440*M23 -> 191 | T23: =1440*N23 -> 579 | U23: =1440*O23 -> 47 | V23: =1440*P23 -> 213
A24: WW04 | B24: 01.19-01.25 | C24: 46043 | D24: 0.53194444 | E24: 46043 | F24: 0.65347222 | G24: 46044 | H24: 0.077777778 | I24: 46044 | J24: 0.13055556 | M24: =(E24+F24)-(C24+D24) -> 0.12152778 | N24: =(G24+H24)-(E24+F24) -> 0.42430556 | O24: =(I24+J24)-(G24+H24) -> 0.052777778 | P24: =(C25+D25)-(I24+J24) -> 0.084027778 | S24: =1440*M24 -> 175 | T24: =1440*N24 -> 611 | U24: =1440*O24 -> 76 | V24: =1440*P24 -> 121
A25: WW04 | B25: 01.19-01.25 | C25: 46044 | D25: 0.21458333 | E25: 46044 | F25: 0.34305556 | G25: 46044 | H25: 0.86805556 | I25: 46044 | J25: 0.94097222 | M25: =(E25+F25)-(C25+D25) -> 0.12847222 | N25: =(G25+H25)-(E25+F25) -> 0.525 | O25: =(I25+J25)-(G25+H25) -> 0.072916667 | P25: =(C26+D26)-(I25+J25) -> 0.28125 | S25: =1440*M25 -> 185 | T25: =1440*N25 -> 756 | U25: =1440*O25 -> 105 | V25: =1440*P25 -> 405
A26: WW04 | B26: 01.19-01.25 | C26: 46045 | D26: 0.22222222 | E26: 46045 | F26: 0.27152778 | G26: 46046 | H26: 0.069444444 | I26: 46046 | J26: 0.1125 | M26: =(E26+F26)-(C26+D26) -> 0.049305556 | N26: =(G26+H26)-(E26+F26) -> 0.79791667 | O26: =(I26+J26)-(G26+H26) -> 0.043055556 | P26: =(C27+D27)-(I26+J26) -> 0.090972222 | S26: =1440*M26 -> 71 | T26: =1440*N26 -> 1149 | U26: =1440*O26 -> 62 | V26: =1440*P26 -> 131
A27: WW04 | B27: 01.19-01.25 | C27: 46046 | D27: 0.20347222 | E27: 46046 | F27: 0.34375 | G27: 46046 | H27: 0.88541667 | I27: 46046 | J27: 0.92361111 | M27: =(E27+F27)-(C27+D27) -> 0.14027778 | N27: =(G27+H27)-(E27+F27) -> 0.54166667 | O27: =(I27+J27)-(G27+H27) -> 0.038194444 | P27: =(C28+D28)-(I27+J27) -> 0.054166667 | S27: =1440*M27 -> 202 | T27: =1440*N27 -> 780 | U27: =1440*O27 -> 55 | V27: =1440*P27 -> 78
A28: WW04 | B28: 01.19-01.25 | C28: 46046 | D28: 0.97777778 | E28: 46047 | F28: 0.13333333 | G28: 46047 | H28: 0.51458333 | I28: 46047 | J28: 0.55277778 | M28: =(E28+F28)-(C28+D28) -> 0.15555556 | N28: =(G28+H28)-(E28+F28) -> 0.38125 | O28: =(I28+J28)-(G28+H28) -> 0.038194444 | P28: =(C29+D29)-(I28+J28) -> 0.04375 | S28: =1440*M28 -> 224 | T28: =1440*N28 -> 549 | U28: =1440*O28 -> 55 | V28: =1440*P28 -> 63
A29: WW05 | B29: 01.26-02.01 | C29: 46047 | D29: 0.59652778 | E29: 46047 | F29: 0.70833333 | G29: 46048 | H29: 0.12777778 | I29: 46048 | J29: 0.17222222 | M29: =(E29+F29)-(C29+D29) -> 0.11180556 | N29: =(G29+H29)-(E29+F29) -> 0.41944444 | O29: =(I29+J29)-(G29+H29) -> 0.044444444 | P29: =(C30+D30)-(I29+J29) -> 0.14861111 | S29: =1440*M29 -> 161 | T29: =1440*N29 -> 604 | U29: =1440*O29 -> 64 | V29: =1440*P29 -> 214 | X29: Total,min | Y29: 11000 | Z29: =SUM(S29:S35) -> 1261 | AA29: =SUM(T29:T35) -> 4118 | AB29: =SUM(U29:U35) -> 374 | AC29: =SUM(V29:V35) -> 4493
A30: WW05 | B30: 01.26-02.01 | C30: 46048 | D30: 0.32083333 | E30: 46048 | F30: 0.40069444 | G30: 46048 | H30: 0.78333333 | I30: 46048 | J30: 0.84027778 | M30: =(E30+F30)-(C30+D30) -> 0.079861111 | N30: =(G30+H30)-(E30+F30) -> 0.38263889 | O30: =(I30+J30)-(G30+H30) -> 0.056944444 | P30: =(C31+D31)-(I30+J30) -> 0.22916667 | S30: =1440*M30 -> 115 | T30: =1440*N30 -> 551 | U30: =1440*O30 -> 82 | V30: =1440*P30 -> 330 | Z30: =(Z29/Y29)*100 -> 11.463636 | AA30: =(AA29/Y29)*100 -> 37.436364 | AB30: =(AB29/Y29)*100 -> 3.4 | AC30: =(AC29/Y29)*100 -> 40.845455
A31: WW05 | B31: 01.26-02.01 | C31: 46049 | D31: 0.069444444 | E31: 46049 | F31: 0.14375 | G31: 46049 | H31: 0.34375 | I31: 46049 | J31: 0.35763889 | M31: =(E31+F31)-(C31+D31) -> 0.074305556 | N31: =(G31+H31)-(E31+F31) -> 0.2 | O31: =(I31+J31)-(G31+H31) -> 0.013888889 | P31: =(C32+D32)-(I31+J31) -> 1.4340278 | S31: =1440*M31 -> 107 | T31: =1440*N31 -> 288 | U31: =1440*O31 -> 20 | V31: =1440*P31 -> 2065
A32: WW05 | B32: 01.26-02.01 | C32: 46050 | D32: 0.79166667 | E32: 46050 | F32: 0.89861111 | G32: 46051 | H32: 0.45833333 | I32: 46051 | J32: 0.50902778 | M32: =(E32+F32)-(C32+D32) -> 0.10694444 | N32: =(G32+H32)-(E32+F32) -> 0.55972222 | O32: =(I32+J32)-(G32+H32) -> 0.050694444 | P32: =(C33+D33)-(I32+J32) -> 1.0208333 | S32: =1440*M32 -> 154 | T32: =1440*N32 -> 806 | U32: =1440*O32 -> 73 | V32: =1440*P32 -> 1470
A33: WW05 | B33: 01.26-02.01 | C33: 46052 | D33: 0.52986111 | E33: 46052 | F33: 0.69236111 | G33: 46053 | H33: 0.25069444 | I33: 46053 | J33: 0.29027778 | M33: =(E33+F33)-(C33+D33) -> 0.1625 | N33: =(G33+H33)-(E33+F33) -> 0.55833333 | O33: =(I33+J33)-(G33+H33) -> 0.039583333 | P33: =(C34+D34)-(I33+J33) -> 0.089583333 | S33: =1440*M33 -> 234 | T33: =1440*N33 -> 804 | U33: =1440*O33 -> 57 | V33: =1440*P33 -> 129
A34: WW05 | B34: 01.26-02.01 | C34: 46053 | D34: 0.37986111 | E34: 46053 | F34: 0.54722222 | G34: 46054 | H34: 0.055555556 | I34: 46054 | J34: 0.084027778 | M34: =(E34+F34)-(C34+D34) -> 0.16736111 | N34: =(G34+H34)-(E34+F34) -> 0.50833333 | O34: =(I34+J34)-(G34+H34) -> 0.028472222 | P34: =(C35+D35)-(I34+J34) -> 0.048611111 | S34: =1440*M34 -> 241 | T34: =1440*N34 -> 732 | U34: =1440*O34 -> 41 | V34: =1440*P34 -> 70
A35: WW05 | B35: 01.26-02.01 | C35: 46054 | D35: 0.13263889 | E35: 46054 | F35: 0.30555556 | G35: 46054 | H35: 0.53680556 | I35: 46054 | J35: 0.5625 | M35: =(E35+F35)-(C35+D35) -> 0.17291667 | N35: =(G35+H35)-(E35+F35) -> 0.23125 | O35: =(I35+J35)-(G35+H35) -> 0.025694444 | P35: =(C36+D36)-(I35+J35) -> 0.14930556 | S35: =1440*M35 -> 249 | T35: =1440*N35 -> 333 | U35: =1440*O35 -> 37 | V35: =1440*P35 -> 215
A36: WW06 | B36: 02.02-02.08 | C36: 46054 | D36: 0.71180556 | E36: 46054 | F36: 0.84166667 | G36: 46055 | H36: 0.33958333 | I36: 46055 | J36: 0.38333333 | M36: =(E36+F36)-(C36+D36) -> 0.12986111 | N36: =(G36+H36)-(E36+F36) -> 0.49791667 | O36: =(I36+J36)-(G36+H36) -> 0.04375 | P36: =(C37+D37)-(I36+J36) -> 3.2673611 | S36: =1440*M36 -> 187 | T36: =1440*N36 -> 717 | U36: =1440*O36 -> 63 | V36: =1440*P36 -> 4705 | X36: Total,min | Y36: 11000 | Z36: =SUM(S36:S41) -> 1193 | AA36: =SUM(T36:T41) -> 3616 | AB36: =SUM(U36:U41) -> 336 | AC36: =SUM(V36:V41) -> 5457
A37: WW06 | B37: 02.02-02.08 | C37: 46058 | D37: 0.65069444 | E37: 46058 | F37: 0.79097222 | G37: 46059 | H37: 0.34652778 | I37: 46059 | J37: 0.38819444 | M37: =(E37+F37)-(C37+D37) -> 0.14027778 | N37: =(G37+H37)-(E37+F37) -> 0.55555556 | O37: =(I37+J37)-(G37+H37) -> 0.041666667 | P37: =(C38+D38)-(I37+J37) -> 0.092361111 | S37: =1440*M37 -> 202 | T37: =1440*N37 -> 800 | U37: =1440*O37 -> 60 | V37: =1440*P37 -> 133 | Z37: =(Z36/Y36)*100 -> 10.845455 | AA37: =(AA36/Y36)*100 -> 32.872727 | AB37: =(AB36/Y36)*100 -> 3.0545455 | AC37: =(AC36/Y36)*100 -> 49.609091
A38: WW06 | B38: 02.02-02.08 | C38: 46059 | D38: 0.48055556 | E38: 46059 | F38: 0.63055556 | G38: 46059 | H38: 0.8625 | I38: 46059 | J38: 0.90416667 | M38: =(E38+F38)-(C38+D38) -> 0.15 | N38: =(G38+H38)-(E38+F38) -> 0.23194444 | O38: =(I38+J38)-(G38+H38) -> 0.041666667 | P38: =(C39+D39)-(I38+J38) -> 0.18611111 | S38: =1440*M38 -> 216 | T38: =1440*N38 -> 334 | U38: =1440*O38 -> 60 | V38: =1440*P38 -> 268
A39: WW06 | B39: 02.02-02.08 | C39: 46060 | D39: 0.090277778 | E39: 46060 | F39: 0.21527778 | G39: 46060 | H39: 0.81666667 | I39: 46060 | J39: 0.85763889 | M39: =(E39+F39)-(C39+D39) -> 0.125 | N39: =(G39+H39)-(E39+F39) -> 0.60138889 | O39: =(I39+J39)-(G39+H39) -> 0.040972222 | P39: =(C40+D40)-(I39+J39) -> 0.075 | S39: =1440*M39 -> 180 | T39: =1440*N39 -> 866 | U39: =1440*O39 -> 59 | V39: =1440*P39 -> 108
A40: WW06 | B40: 02.02-02.08 | C40: 46060 | D40: 0.93263889 | E40: 46061 | F40: 0.086111111 | G40: 46061 | H40: 0.21666667 | I40: 46061 | J40: 0.24791667 | M40: =(E40+F40)-(C40+D40) -> 0.15347222 | N40: =(G40+H40)-(E40+F40) -> 0.13055556 | O40: =(I40+J40)-(G40+H40) -> 0.03125 | P40: =(C41+D41)-(I40+J40) -> 0.12361111 | S40: =1440*M40 -> 221 | T40: =1440*N40 -> 188 | U40: =1440*O40 -> 45 | V40: =1440*P40 -> 178
...

Sheet Total Tape Length per Workweek
D8: WW10 | E8: WW11 | F8: WW12 | G8: WW13 | H8: WW14 | I8: WW15 | J8: WW16 | K8: WW17 | L8: WW18 | M8: WW19 | N8: WW20 | O8: WW21 | P8: WW22 | Q8: WW23 | R8: WW24 | S8: WW25 | T8: WW26 | U8: WW27 | V8: WW28 | W8: WW29 | X8: WW30 | Y8: WW31 | Z8: WW32 | AA8: WW33 | AB8: WW34 | AC8: WW35
C9: Actual Deposited Tape | D9: =SUM('Dep Cycle Time Monitoring'!H4:H13) -> 15415 | E9: =SUM('Dep Cycle Time Monitoring'!H15:H21) -> 9873 | F9: =SUM('Dep Cycle Time Monitoring'!H22:H28) -> 10883 | G9: =SUM('Dep Cycle Time Monitoring'!H29:H38) -> 13258 | H9: =SUM('Dep Cycle Time Monitoring'!H39:H39) -> 0 | I9: =SUM('Dep Cycle Time Monitoring'!#REF!) -> #REF! | J9: =SUM('Dep Cycle Time Monitoring'!#REF!) -> #REF! | K9: =SUM('Dep Cycle Time Monitoring'!#REF!) -> #REF! | M9: =SUM('Dep Cycle Time Monitoring'!#REF!) -> #REF! | N9: =SUM('Dep Cycle Time Monitoring'!#REF!) -> #REF! | O9: =SUM('Dep Cycle Time Monitoring'!#REF!) -> #REF! | P9: =SUM('Dep Cycle Time Monitoring'!#REF!) -> #REF! | Q9: =SUM('Dep Cycle Time Monitoring'!#REF!) -> #REF! | R9: =SUM('Dep Cycle Time Monitoring'!#REF!) -> #REF! | S9: =SUM('Dep Cycle Time Monitoring'!#REF!) -> #REF! | T9: =SUM('Dep Cycle Time Monitoring'!#REF!) -> #REF! | ... Y9: =SUM('Dep Cycle Time Monitoring'!#REF!) -> #REF!
C10: Target | D10: 15000 | E10: 15000 | F10: 15000 | G10: 15000 | H10: 15000 | I10: 15000 | J10: 15000 | K10: 15000 | L10: 15000 | M10: 15000 | N10: 15000 | O10: 15000 | P10: 15000 | Q10: 15000 | R10: 15000 | S10: 15000 | T10: 15000 | U10: 15000 | V10: 15000 | W10: 15000 | X10: 15000 | Y10: 15000 | Z10: 15000 | AA10: 15000 | AB10: 15000 | AC10: 15000

Sheet 4-March
B2: Process Parameter Conditions
B3: PM1 | C3: 4000
B4: PM2 | C4: 3000
B5: PM3 | C5: 1000
B6: Rate in IBAD
B7: Rate in EPI | C7: 13
B8: Speed (m/min) | C8: 3
F14: Length | H14: Event
N24: ATTACH/PASTE GREENSCAN HERE
N46: ATTACH/PASTE GREENSCAN HERE

Sheet work week

Sheet Sheet1
B1: Metrics | C1: UOM | D1: Target | E1: Actual | M1: Results | N1: Delta
E2: WW20 | F2: WW21 | G2: WW22 | H2: WW23 | I2: WW24 | J2: WW25 | K2: WW26 | L2: WW27
B3: Production Output | C3: Km/week | D3: 15 km/week | E3: 16k
B6: Production Yield | C6: % | D6: 0.97 | E6: 0.98
B9: In-Process Defects | C9: % | D9: >2% | E9: 1.50% | O9: Data will be gathered thru database (Egun1OFF, cut from eval samples)
B12: Set up time | C12: Average Minutes | D12: >220 | E12: 210
B15: Average Ic | C15: Amperes/Km | D15: 600 | E15: 620 | O15: Get the average weekly Ic
B18: XRD | C18: Angle Degrees | D18: <7Deg | O18: Get the average weekly XRD

Sheet Detail1
A1: Details for Sum of E-Gun 1 OFF Occurrence - Workweek: WW44, E-Gun 1 OFF Occurrence: 0 (+)
A3: Workweek | B3: Tape Number | C3: ION Source OFF | D3: E-Gun 1 OFF Occurrence | E3: E-Gun 2 OFF Occurrence | F3: Grids
A4: WW44 | B4: #2750(1197-0)#2740(1616-966) | C4: 0 | D4: 3 | E4: 0 | F4: KTM023
A5: WW44 | B5: #2750(1317-0) #2736(1255-0) | C5: 0 | D5: 2 | E5: 0 | F5: KTM023
A6: WW44 | B6: #2728(1450-0) | C6: 0 | D6: 1 | E6: 0 | F6: KTM023
A7: WW44 | B7: #2736(1655-1255) | C7: 0 | D7: 0 | E7: 0 | F7: R009
A8: WW44 | B8: #2738(1613-0) | C8: 0 | D8: 3 | E8: 0 | F8: R009
A9: WW44 | B9: #2726(1617-0) | C9: 0 | D9: 0 | E9: 0 | F9: R009
A10: WW44 | B10: #2730(1400-1200) | C10: 0 | D10: 0 | E10: 0 | F10: R009
A11: WW44 | B11: #2730(1653-1400) | C11: 1 | D11: 1 | E11: 0 | F11: R009
A12: WW44 | B12: #2732(1276-0) | C12: 0 | D12: 0 | E12: 0 | F12: R009
A13: WW44 | B13: #2732(1656-1276) | C13: 3 | D13: 0 | E13: 0 | F13: R009
A14: WW44 | B14: #2730(1000-0) | C14: 0 | D14: 0 | E14: 0 | F14: R117

Sheet COUNTS
A1: Workweek | B1: Tape Number | C1: ION Source OFF | D1: E-Gun 1 OFF Occurrence | E1: E-Gun 2 OFF Occurrence | F1: Grids
A2: WW02 | B2: #2900(1662-0) | C2: 0 | D2: 1 | E2: 0 | F2: KTM023
A3: WW02 | B3: #2902(1665-0) | C3: 0 | D3: 0 | E3: 0 | F3: KTM027
A4: WW02 | B4: #2902(1665-0) | C4: 0 | D4: 0 | E4: 0 | F4: KTM027
A5: WW02 | B5: #2904(1662-0) | C5: 0 | D5: 0 | E5: 0 | F5: KTM027
A6: WW02 | B6: #2906(1536-0) #2880(1691-1534) | C6: 0 | D6: 0 | E6: 0 | F6: KTM027
A7: WW02 | B7: #2898(985-1427) | C7: 0 | D7: 0 | E7: 0 | F7: KTM027 | O7: E-Gun 1 OFF Occurrence | P7: (Multiple Items)
A8: WW02 | B8: #2898(339-985) #2892(1385-0) | C8: 0 | D8: 0 | E8: 0 | F8: KTM027
A9: WW02 | B9: #2912(1620-0) | C9: 0 | D9: 0 | E9: 0 | F9: KTM027 | P9: Column Labels
A10: WW02 | B10: #2914(1656-0) | C10: 0 | D10: 2 | E10: 0 | F10: KTM027 | P10: WW02 | Q10: WW03 | R10: WW04 | S10: WW05 | T10: WW06 | U10: WW07 | V10: WW08 | W10: WW09 | X10: WW10 | Y10: WW11 | Z10: WW12 | AA10: WW13 | AB10: WW14 | AC10: WW15 | AD10: WW16 | AE10: WW17 | AF10: WW18 | AG10: WW19 | AH10: WW20 | AI10: Grand Total
A11: WW02 | B11: #2910(570-0) #2910(1076-570) #2908(825-0) | C11: 0 | D11: 0 | E11: 0 | F11: KTM027 | O11: Sum of E-Gun 1 OFF Occurrence | P11: 3 | Q11: 5 | R11: 9 | S11: 0 | T11: 2 | U11: 4 | V11: 9 | W11: 4 | X11: 2 | Y11: 0 | Z11: 0 | AA11: 6 | AB11: 4 | AC11: 0 | AD11: 5 | AE11: 2 | AF11: 0 | AG11: 0 | AH11: 0 | AI11: 55
A12: WW03 | B12: #2918(1389-0)#2920(1356-0) | C12: 0 | D12: 1 | E12: 0 | F12: KTM027
A13: WW03 | B13: #2922(1403-0) #2916(1397-700) | C13: 0 | D13: 2 | E13: 1 | F13: KTM027
A14: WW03 | B14: #2898(339-0)#2926(1661-926)#2926(705-0) | C14: 0 | D14: 0 | E14: 0 | F14: KTM027
A15: WW03 | B15: #2930(1500-0) | C15: 0 | D15: 0 | E15: 0 | F15: KTM027
A16: WW03 | B16: #EXP1-20 | C16: 0 | D16: 0 | E16: 0 | F16: KTM027 | O16: E-Gun 2 OFF Occurrence | P16: (Multiple Items)
A17: WW03 | B17: #2940(1453-0) | C17: 0 | D17: 1 | E17: 0 | F17: KTM023
A18: WW03 | B18: #2932(1500-0) | C18: 0 | D18: 0 | E18: 0 | F18: KTM023 | P18: Column Labels
A19: WW03 | B19: #2954(1398-0) | C19: 0 | D19: 1 | E19: 0 | F19: KTM023 | P19: WW02 | Q19: WW03 | R19: WW04 | S19: WW05 | T19: WW06 | U19: WW07 | V19: WW08 | W19: WW09 | X19: WW10 | Y19: WW11 | Z19: WW12 | AA19: WW13 | AB19: WW14 | AC19: WW15 | AD19: WW16 | AE19: WW17 | AF19: WW18 | AG19: WW19 | AH19: WW20 | AI19: Grand Total
A20: WW03 | B20: #2952(1394-0)#2916(690-0) | C20: 0 | D20: 0 | E20: 0 | F20: KTM023 | O20: Sum of E-Gun 2 OFF Occurrence | P20: 0 | Q20: 1 | R20: 1 | S20: 0 | T20: 0 | U20: 1 | V20: 0 | W20: 1 | X20: 1 | Y20: 1 | Z20: 0 | AA20: 0 | AB20: 0 | AC20: 0 | AD20: 1 | AE20: 0 | AF20: 0 | AG20: 0 | AH20: 0 | AI20: 7
A21: WW04 | B21: #2898(1662-1427) #2910(1364-1101) | C21: 0 | D21: 0 | E21: 0 | F21: KTM023
A22: WW04 | B22: #2950(1684-898) #2950(896-0) | C22: 0 | D22: 1 | E22: 0 | F22: KTM023
A23: WW04 | B23: #2942(1633-1427) #29542(1427-16) | C23: 0 | D23: 0 | E23: 1 | F23: KTM023
A24: WW04 | B24: #2946(339-0)#2944(1328-4)+50mDMY | C24: 0 | D24: 1 | E24: 0 | F24: KTM023 | O24: ION Source OFF | P24: (Multiple Items)
A25: WW04 | B25: #2948(1656-906)#2956(1398-0) | C25: 0 | D25: 5 | E25: 0 | F25: KTM023
A26: WW04 | B26: #2868 (000-195)#2944 (1659-1328)#2946 (339-1665) RnD | C26: 0 | D26: 1 | E26: 0 | F26: KTM023 | P26: Column Labels
A27: WW04 | B27: #2928(1666-844) #2960(1395-0) | C27: 0 | D27: 1 | E27: 0 | F27: KTM023 | P27: WW02 | Q27: WW03 | R27: WW04 | S27: WW05 | T27: WW06 | U27: WW07 | V27: WW08 | W27: WW09 | X27: WW10 | Y27: WW11 | Z27: WW12 | AA27: WW13 | AB27: WW14 | AC27: WW15 | AD27: WW16 | AE27: WW17 | AF27: WW18 | AG27: WW19 | AH27: WW20 | AI27: Grand Total
A28: WW04 | B28: #2958(1531-355) #2958(350-000) | C28: 0 | D28: 0 | E28: 0 | F28: KTM023 | O28: Sum of ION Source OFF | P28: 0 | Q28: 0 | R28: 0 | S28: 0 | T28: 2 | U28: 0 | V28: 0 | W28: 1 | X28: 0 | Y28: 4 | Z28: 3 | AA28: 0 | AB28: 0 | AC28: 0 | AD28: 2 | AE28: 0 | AF28: 0 | AG28: 0 | AH28: 0 | AI28: 12
A29: WW05 | B29: #2970(962-697)#2964(1397-0) | C29: 0 | D29: 0 | E29: 0 | F29: KTM023
A30: WW05 | B30: #2970(680-0)#2968(848-0) | C30: 0 | D30: 0 | E30: 0 | F30: KTM023
A31: WW05 | B31: #2920(1556-1656)#2978(1100-1224) YB production | C31: 0 | D31: 0 | E31: 0 | F31: KTM023
A32: WW05 | B32: #2978(500-0)#2986(1396-0) | C32: 0 | D32: 0 | E32: 0 | F32: R009
A33: WW05 | B33: #2986(1396-0) #2978(500-0) | C33: 0 | D33: 0 | E33: 0 | F33: R009
A34: WW05 | B34: #2976(896-0) #2966(1394-0) | C34: 0 | D34: 0 | E34: 0 | F34: KTM027
A35: WW05 | B35: #2978(500-1100)#2988(1396-0) | C35: 0 | D35: 0 | E35: 0 | F35: KTM027
A36: WW05 | B36: RnD | C36: 0 | D36: 0 | E36: 0 | F36: KTM027
A37: WW06 | B37: #3004(1361-000) #2962(670-000) | C37: 0 | D37: 2 | E37: 0 | F37: KTM027
A38: WW06 | B38: #3000(19-359) #3000(483-1058) #2982(1365-0) | C38: 0 | D38: 0 | E38: 0 | F38: KTM027
A39: WW06 | B39: #3010(1-336)#3010(336-631) | C39: 0 | D39: 0 | E39: 0 | F39: KTM027
A40: WW06 | B40: #3012(1098-0)#3014(1380-0) | C40: 2 | D40: 0 | E40: 0 | F40: KTM027
...
